Workbook
Name BusinessCapabilities: #REF!
Name Domain: #REF!

Sheet Sri - Resource Master -May 
A1: Yash Emp ID | B1: Employee Name | C1: Grade | D1: Client | E1: Project | F1: Skill | G1: Delivery Manager | H1: IRM Name | I1: SRM Name | J1: Client Manager | M1: Allocation Type | N1: Billing Rate | O1: %Profit
A2: 1000111 | B2: Madhu Smitha | C2: E5 | D2: JohnDeere | E2: TCI Staffing | F2: SAP FICO | G2: Srivijaya Pichika | H2: Srivijaya Pichika | I2: Srivijaya Pichika | J2: Dipesh Parekh | K2: =VLOOKUP(A2,'Employee detail'!$B$1:$F$220,5,0) -> IT Finance | L2: IT Finance | M2: Billable | N2: 2100 | O2: 0.42911905
A3: 1009797 | B3: Vivek Anaskar | C3: E2 | D3: JohnDeere | E3: TCI Staffing | F3: SAP HCM | G3: Srivijaya Pichika | H3: Nishanta Devadiga | I3: Srivijaya Pichika | J3: Suresh Manthathi | K3: =VLOOKUP(A3,'Employee detail'!$B$1:$F$220,5,0) -> HCM | L3: HR | M3: Billable | N3: 2100 | O3: 0.30933333
A4: 1601237 | B4: Akshay Upalekar | C4: C | D4: JohnDeere | E4: TCI Staffing | F4: SAP EWM | G4: Srivijaya Pichika | H4: Nishanta Devadiga | I4: Srivijaya Pichika | J4: Venkata Anil Krishna Poluri | K4: =VLOOKUP(A4,'Employee detail'!$B$1:$F$220,5,0) -> PDC | M4: Billable | N4: 1800 | O4: 0.33333333
A5: 1005949 | B5: B Sreedhar Reddy | C5: E6 | D5: JohnDeere | E5: TCI Staffing | F5: SAP CRM | G5: Srivijaya Pichika | H5: Srivijaya Pichika | I5: Srivijaya Pichika | J5: Sreedhar Nimmagadda | K5: =VLOOKUP(A5,'Employee detail'!$B$1:$F$220,5,0) -> PDC | L5: PDC | M5: Billable | N5: 1500 | O5: -0.022566667
A6: 1012709 | B6: Kovvuru Chandra Reddy | C6: E1 | D6: JohnDeere | E6: TCI Staffing | F6: SAP BODS | G6: Srivijaya Pichika | H6: Srivijaya Pichika | I6: Srivijaya Pichika | J6: Pranjali Patil | K6: =VLOOKUP(A6,'Employee detail'!$B$1:$F$220,5,0) -> PDC | L6: PDC | M6: Billable | N6: 1400 | O6: 0.63885714
A7: 1005201 | B7: Vijaya Ganapa | C7: E2 | D7: JohnDeere | E7: TCI Staffing | F7: SAP SuccessFactors | G7: Srivijaya Pichika | H7: Nishanta Devadiga | I7: Sharath Panaggamula | J7: Suresh Manthathi | K7: =VLOOKUP(A7,'Employee detail'!$B$1:$F$220,5,0) -> HCM | L7: HR | M7: Billable | N7: 1800 | O7: 0.54711111
A8: 1012589 | B8: Sowjanya Parthasarathi | C8: E2 | D8: JohnDeere | E8: System Interoperability | F8: SAP PI/CPI | G8: Srivijaya Pichika | H8: Abir Sarkar | I8: Srivijaya Pichika | J8: Mahesh Jayaraman | K8: =VLOOKUP(A8,'Employee detail'!$B$1:$F$220,5,0) -> MSP | L8: MSP | M8: Billable | N8: 1640 | O8: 0.18699187
A9: 1012968 | B9: Narasimha Reddy Kanubuddi | C9: E2 | D9: JohnDeere | E9: TCI Staffing | F9: SAP ABAP HANA | G9: Srivijaya Pichika | H9: Nishanta Devadiga | I9: Srivijaya Pichika | J9: Atul Kudegave | K9: MSP | M9: Billable | N9: 1800 | O9: 0.54552778
A10: 1014344 | B10: Sathi Manikanta Ramareddy | C10: E1 | D10: JohnDeere | E10: TCI Staffing | F10: SAP BODS | G10: Srivijaya Pichika | H10: Srivijaya Pichika | I10: Srivijaya Pichika | J10: Pranjali Patil | K10: =VLOOKUP(A10,'Employee detail'!$B$1:$F$220,5,0) -> PDC | M10: Billable | N10: 1700 | O10: 0.72985294
A11: 1601466 | B11: Sreedevi Varahala | C11: C | D11: JohnDeere | E11: TCI Staffing | F11: SAP ABAP CRM | G11: Srivijaya Pichika | H11: Srivijaya Pichika | I11: Srivijaya Pichika | J11: Sreedhar Nimmagadda | K11: =VLOOKUP(A11,'Employee detail'!$B$1:$F$220,5,0) -> PDC | M11: Billable | N11: 2200 | O11: 0.43181818
A12: 1600057 | B12: Afsar Mohammad | C12: E2 | D12: JohnDeere | E12: TCI Staffing | F12: SAP BODS | G12: Srivijaya Pichika | H12: Srivijaya Pichika | I12: Srivijaya Pichika | J12: Pranjali Patil | K12: =VLOOKUP(A12,'Employee detail'!$B$1:$F$220,5,0) -> PDC | M12: Billable | N12: 1800 | O12: 0.45508333
A13: 1601535 | B13: Yanamadala Sasidhar | C13: C | D13: JohnDeere | E13: TCI Staffing | F13: SAP ABAP CRM | G13: Srivijaya Pichika | H13: Srivijaya Pichika | I13: Srivijaya Pichika | J13: Sreedhar Nimmagadda | K13: =VLOOKUP(A13,'Employee detail'!$B$1:$F$220,5,0) -> PDC | M13: Billable | N13: 2350 | O13: 0.25531915
A14: 1013812 | B14: Jeshwant Kolan | C14: E2 | D14: JohnDeere | E14: TCI Staffing | F14: SAP FICO | G14: Srivijaya Pichika | H14: Nishanta Devadiga | I14: Srivijaya Pichika | J14: Shital Kupwade | K14: =VLOOKUP(A14,'Employee detail'!$B$1:$F$220,5,0) -> IT Finance | M14: Billable | N14: 1400 | O14: 0.43771429
A15: 1004516 | B15: Bhaskar Yellamanchili | C15: E3 | D15: JohnDeere | E15: TCI Staffing | F15: SAP HR | G15: Srivijaya Pichika | H15: Nishanta Devadiga | I15: Sharath Panaggamula | J15: Suresh Manthathi | K15: =VLOOKUP(A15,'Employee detail'!$B$1:$F$220,5,0) -> HCM | M15: Billable | N15: 1800 | O15: 0.49072222
A16: 1016969 | B16: Venkataraman J | C16: E3 | D16: JohnDeere | E16: TCI Staffing | F16: SAP ABAP HANA | G16: Srivijaya Pichika | H16: Srivijaya Pichika | I16: Srivijaya Pichika | J16: Felipe Engleman | K16: =VLOOKUP(A16,'Employee detail'!$B$1:$F$220,5,0) -> PDP | M16: Billable | N16: 1800 | O16: 0.30238889
A17: 1017777 | B17: Swati Patil | C17: E3 | D17: JohnDeere | E17: TCI Staffing | F17: SAP ABAP HANA | G17: Srivijaya Pichika | H17: Srivijaya Pichika | I17: Srivijaya Pichika | J17: Amit Koul | K17: =VLOOKUP(A17,'Employee detail'!$B$1:$F$220,5,0) -> CPS | M17: Billable | N17: 2100 | O17: 0.39047619
A18: 1601627 | B18: Sravani A | C18: C | D18: JohnDeere | E18: System Interoperability | F18: SAP ABAP HANA | G18: Srivijaya Pichika | H18: Abir Sarkar | I18: Srivijaya Pichika | J18: Mahesh Jayaraman | K18: =VLOOKUP(A18,'Employee detail'!$B$1:$F$220,5,0) -> MSP | M18: Billable | N18: 2100 | O18: 0.3015873
A19: 1601630 | B19: B Kiran Kumar | C19: C | D19: JohnDeere | E19: TCI Staffing | F19: SAP ABAP CRM | G19: Srivijaya Pichika | H19: Srivijaya Pichika | I19: Srivijaya Pichika | J19: Sreedhar Nimmagadda | K19: =VLOOKUP(A19,'Employee detail'!$B$1:$F$220,5,0) -> PDC | M19: Billable | N19: 2350 | O19: 0.25531915
A20: 1100051 | B20: Akash Bhutwani | C20: E2 | D20: JohnDeere | E20: TCI Staffing | F20: SAP ABAP HANA | G20: Srivijaya Pichika | H20: Nishanta Devadiga | I20: Srivijaya Pichika | J20: Dipesh Parekh | K20: =VLOOKUP(A20,'Employee detail'!$B$1:$F$220,5,0) -> IT Finance | M20: Billable | N20: 1700 | O20: 0.58811765
A21: 1601656 | B21: Nagam Rammohan | C21: C | D21: JohnDeere | E21: TCI Staffing | F21: SAP ABAP CRM | G21: Srivijaya Pichika | H21: Srivijaya Pichika | I21: Srivijaya Pichika | J21: Sreedhar Nimmagadda | K21: =VLOOKUP(A21,'Employee detail'!$B$1:$F$220,5,0) -> PDC | M21: Billable | N21: 2100 | O21: 0.22857143
... A35: 1602253 | B35: Tisha Haria | C35: C | D35: JohnDeere | E35: TCI Staffing | F35: SAP ABAP CRM | G35: Srivijaya Pichika | H35: Srivijaya Pichika | I35: Srivijaya Pichika | J35: Sreedhar Nimmagadda | K35: =VLOOKUP(A35,'Employee detail'!$B$1:$F$220,5,0) -> PDC | M35: Billable | N35: 2400 | O35: 0.31916667
A36: 1602284 | B36: Naga Jyothi Maddali | C36: C | D36: JohnDeere | E36: TCI Staffing | F36: SAP ABAP CRM | G36: Srivijaya Pichika | H36: Srivijaya Pichika | I36: Srivijaya Pichika | J36: Sreedhar Nimmagadda | K36: PDC | M36: Billable | N36: 2100 | O36: 0.29
J41: 49 | M41: 44 | N41: =J41+M41 -> 93 | O41: =N41/2 -> 46.5

Sheet for Kishore use
A1: Employee ID | B1: Employee Name | C1: Employee Status | D1: Employee Type | E1: Designation | F1: IRM | G1: Parent BG | H1: Parent BU | I1: Competency | J1: Allocation Type | K1: Sub Allocation Type | L1: Allocation % | M1: Hourly Bill Rates | N1: Conversion Factor | O1: Run Rate (Monthly) | P1: CTC | Q1: OH | R1: CTC(U) | S1: OH(U) | T1: Emp Cost | U1: Profit | V1: Profit% | W1: Project Name | X1: Group | Y1: Project Manager | Z1: Delivery Manager | AA1: Project BUHSSUH | AB1: Project BGHSSGH | AC1: Project BG | AD1: Project BU | AE1: Project Hour Day | AF1: Project Currency
A2: 1601783 | B2: Abhishek Premsing Jadhav | C2: Active | D2: Contractual | E2: Contractor | F2: Rajesh Radhakrishnan Nair | G2: BG5 | H2: BG5-BU11 | I2: Microsoft | J2: Billable | K2: Billable | L2: 100 | M2: 1800 | N2: 0.012195122 | O2: =(L2/100)*M2*N2*(20*AE2) -> 3951.2195 | P2: 2430000 | Q2: 300000 | R2: =IFERROR(P2*(L2/100),"-") -> 2430000 | S2: =IFERROR(Q2*(L2/100),"-") -> 300000 | T2: =IFERROR((R2+S2)/(86*12),"-") -> 2645.3488 | U2: =O2-T2 -> 1305.8707 | V2: =U2/O2 -> 0.33049813 | W2: JD-TCI-BG4-BU4-CAP | X2: CAP | Y2: Rajesh Radhakrishnan Nair | Z2: Seshakishore Kumar Kollipara | AA2: Shailendra Gupta | AB2: Arun Kumar Mishra | AC2: BG4 | AD2: BG4-BU4 | AE2: 9 | AF2: INR
A3: 1102379 | B3: Pankaj Kumar Singh | C3: Active | D3: Permanent | E3: Sr. Software Engineer | F3: Rajesh Radhakrishnan Nair | G3: BG4 | H3: BG4-BU4 | I3: Java | J3: Billable | K3: Billable | L3: 100 | M3: 1700 | N3: 0.012195122 | O3: =(L3/100)*M3*N3*(20*AE3) -> 3731.7073 | P3: 1389395 | Q3: 300000 | R3: =IFERROR(P3*(L3/100),"-") -> 1389395 | S3: =IFERROR(Q3*(L3/100),"-") -> 300000 | T3: =IFERROR((R3+S3)/(86*12),"-") -> 1637.0107 | U3: =O3-T3 -> 2094.6966 | V3: =U3/O3 -> 0.56132393 | W3: JD-TCI-BG4-BU4-CAP | X3: CAP | Y3: Rajesh Radhakrishnan Nair | Z3: Seshakishore Kumar Kollipara | AA3: Shailendra Gupta | AB3: Arun Kumar Mishra | AC3: BG4 | AD3: BG4-BU4 | AE3: 9 | AF3: INR
A4: 1102381 | B4: Lakshya Sharma | C4: Active | D4: Permanent | E4: Sr. Software Engineer | F4: Rajesh Radhakrishnan Nair | G4: BG4 | H4: BG4-BU4 | I4: Mobility | J4: Billable | K4: Billable | L4: 100 | M4: 1400 | N4: 0.012195122 | O4: =(L4/100)*M4*N4*(20*AE4) -> 3073.1707 | P4: 1389395 | Q4: 300000 | R4: =IFERROR(P4*(L4/100),"-") -> 1389395 | S4: =IFERROR(Q4*(L4/100),"-") -> 300000 | T4: =IFERROR((R4+S4)/(86*12),"-") -> 1637.0107 | U4: =O4-T4 -> 1436.16 | V4: =U4/O4 -> 0.46732192 | W4: JD-TCI-BG4-BU4-CAP | X4: CAP | Y4: Rajesh Radhakrishnan Nair | Z4: Seshakishore Kumar Kollipara | AA4: Shailendra Gupta | AB4: Arun Kumar Mishra | AC4: BG4 | AD4: BG4-BU4 | AE4: 9 | AF4: INR
A5: 1014127 | B5: Mayuri Nandkishorji Mundada | C5: Active | D5: Permanent | E5: Software Engineer | F5: Rajesh Radhakrishnan Nair | G5: BG4 | H5: BG4-BU4 | I5: Java | J5: Billable | K5: Billable | L5: 100 | M5: 1400 | N5: 0.012195122 | O5: =(L5/100)*M5*N5*(20*AE5) -> 3073.1707 | P5: 487704 | Q5: 300000 | R5: =IFERROR(P5*(L5/100),"-") -> 487704 | S5: =IFERROR(Q5*(L5/100),"-") -> 300000 | T5: =IFERROR((R5+S5)/(86*12),"-") -> 763.27907 | U5: =O5-T5 -> 2309.8917 | V5: =U5/O5 -> 0.75163141 | W5: JD-TCI-BG4-BU4-CAP | X5: CAP | Y5: Rajesh Radhakrishnan Nair | Z5: Seshakishore Kumar Kollipara | AA5: Shailendra Gupta | AB5: Arun Kumar Mishra | AC5: BG4 | AD5: BG4-BU4 | AE5: 9 | AF5: INR
A6: 1016125 | B6: Ashwini Jagannath Lohar | C6: Active | D6: Permanent | E6: Software Engineer | F6: Rajesh Radhakrishnan Nair | G6: BG4 | H6: BG4-BU4 | I6: Java | J6: Billable | K6: Billable | L6: 100 | M6: 1400 | N6: 0.012195122 | O6: =(L6/100)*M6*N6*(20*AE6) -> 3073.1707 | P6: 695604 | Q6: 300000 | R6: =IFERROR(P6*(L6/100),"-") -> 695604 | S6: =IFERROR(Q6*(L6/100),"-") -> 300000 | T6: =IFERROR((R6+S6)/(86*12),"-") -> 964.73256 | U6: =O6-T6 -> 2108.4382 | V6: =U6/O6 -> 0.68607909 | W6: JD-TCI-BG4-BU4-CAP | X6: CAP | Y6: Rajesh Radhakrishnan Nair | Z6: Seshakishore Kumar Kollipara | AA6: Shailendra Gupta | AB6: Arun Kumar Mishra | AC6: BG4 | AD6: BG4-BU4 | AE6: 9 | AF6: INR
A7: 1017632 | B7: Ajinkya Sharad Mane | C7: Active | D7: Permanent | E7: UI Specialist | F7: Rajesh Radhakrishnan Nair | G7: BG5 | H7: BG5-BU1 | I7: User Interface (UI) | J7: Billable | K7: Billable | L7: 100 | M7: 1400 | N7: 0.012195122 | O7: =(L7/100)*M7*N7*(20*AE7) -> 3073.1707 | P7: 884508 | Q7: 300000 | R7: =IFERROR(P7*(L7/100),"-") -> 884508 | S7: =IFERROR(Q7*(L7/100),"-") -> 300000 | T7: =IFERROR((R7+S7)/(86*12),"-") -> 1147.7791 | U7: =O7-T7 -> 1925.3917 | V7: =U7/O7 -> 0.62651633 | W7: JD-TCI-BG4-BU4-CAP | X7: CAP | Y7: Rajesh Radhakrishnan Nair | Z7: Seshakishore Kumar Kollipara | AA7: Shailendra Gupta | AB7: Arun Kumar Mishra | AC7: BG4 | AD7: BG4-BU4 | AE7: 9 | AF7: INR
A8: 1016107 | B8: Shekhar Kumar Jha | C8: Active | D8: Permanent | E8: Sr. Software Engineer | F8: Rajesh Radhakrishnan Nair | G8: BG4 | H8: BG4-BU4 | I8: Java | J8: Billable | K8: Billable | L8: 100 | M8: 1400 | N8: 0.012195122 | O8: =(L8/100)*M8*N8*(20*AE8) -> 3073.1707 | P8: 956304 | Q8: 300000 | R8: =IFERROR(P8*(L8/100),"-") -> 956304 | S8: =IFERROR(Q8*(L8/100),"-") -> 300000 | T8: =IFERROR((R8+S8)/(86*12),"-") -> 1217.3488 | U8: =O8-T8 -> 1855.8219 | V8: =U8/O8 -> 0.60387855 | W8: JD-TCI-BG4-BU4-CAP | X8: CAP | Y8: Rajesh Radhakrishnan Nair | Z8: Seshakishore Kumar Kollipara | AA8: Shailendra Gupta | AB8: Arun Kumar Mishra | AC8: BG4 | AD8: BG4-BU4 | AE8: 9 | AF8: INR
A9: 1011367 | B9: Avinash Kumar Singh | C9: Active | D9: Permanent | E9: Software Engineer | F9: Rajesh Radhakrishnan Nair | G9: BG5 | H9: BG5-BU11 | I9: Microsoft | J9: Billable | K9: Billable | L9: 100 | M9: 1400 | N9: 0.012195122 | O9: =(L9/100)*M9*N9*(20*AE9) -> 3073.1707 | P9: 1100004 | Q9: 300000 | R9: =IFERROR(P9*(L9/100),"-") -> 1100004 | S9: =IFERROR(Q9*(L9/100),"-") -> 300000 | T9: =IFERROR((R9+S9)/(86*12),"-") -> 1356.593 | U9: =O9-T9 -> 1716.5777 | V9: =U9/O9 -> 0.55856894 | W9: JD-TCI-BG4-BU4-CAP | X9: CAP | Y9: Rajesh Radhakrishnan Nair | Z9: Seshakishore Kumar Kollipara | AA9: Shailendra Gupta | AB9: Arun Kumar Mishra | AC9: BG4 | AD9: BG4-BU4 | AE9: 9 | AF9: INR
A10: 1100645 | B10: Ankita Ajay Chaudhari | C10: Active | D10: Permanent | E10: Associate Consultant | F10: Rajesh Radhakrishnan Nair | G10: BG5 | H10: BG5-BU11 | I10: Microsoft | J10: Billable | K10: Billable | L10: 100 | M10: 1400 | N10: 0.012195122 | O10: =(L10/100)*M10*N10*(20*AE10) -> 3073.1707 | P10: 1100004 | Q10: 300000 | R10: =IFERROR(P10*(L10/100),"-") -> 1100004 | S10: =IFERROR(Q10*(L10/100),"-") -> 300000 | T10: =IFERROR((R10+S10)/(86*12),"-") -> 1356.593 | U10: =O10-T10 -> 1716.5777 | V10: =U10/O10 -> 0.55856894 | W10: JD-TCI-BG4-BU4-CAP | X10: CAP | Y10: Rajesh Radhakrishnan Nair | Z10: Seshakishore Kumar Kollipara | AA10: Shailendra Gupta | AB10: Arun Kumar Mishra | AC10: BG4 | AD10: BG4-BU4 | AE10: 9 | AF10: INR
A11: 1017087 | B11: Shubham Sanjay Deshpande | C11: Active | D11: Permanent | E11: Sr. Software Engineer | F11: Rajesh Radhakrishnan Nair | G11: BG4 | H11: BG4-BU4 | I11: Java | J11: Billable | K11: Billable | L11: 100 | M11: 1200 | N11: 0.012195122 | O11: =(L11/100)*M11*N11*(20*AE11) -> 2634.1463 | P11: 1146804 | Q11: 300000 | R11: =IFERROR(P11*(L11/100),"-") -> 1146804 | S11: =IFERROR(Q11*(L11/100),"-") -> 300000 | T11: =IFERROR((R11+S11)/(86*12),"-") -> 1401.9419 | U11: =O11-T11 -> 1232.2045 | V11: =U11/O11 -> 0.46778133 | W11: JD-TCI-BG4-BU4-CAP | X11: CAP | Y11: Rajesh Radhakrishnan Nair | Z11: Seshakishore Kumar Kollipara | AA11: Shailendra Gupta | AB11: Arun Kumar Mishra | AC11: BG4 | AD11: BG4-BU4 | AE11: 9 | AF11: INR
A12: 1100745 | B12: Pushpak Satish Bhambar | C12: Active | D12: Permanent | E12: Sr. Software Engineer | F12: Rajesh Radhakrishnan Nair | G12: BG4 | H12: BG4-BU4 | I12: Java | J12: Billable | K12: Billable | L12: 100 | M12: 1200 | N12: 0.012195122 | O12: =(L12/100)*M12*N12*(20*AE12) -> 2634.1463 | P12: 1200000 | Q12: 300000 | R12: =IFERROR(P12*(L12/100),"-") -> 1200000 | S12: =IFERROR(Q12*(L12/100),"-") -> 300000 | T12: =IFERROR((R12+S12)/(86*12),"-") -> 1453.4884 | U12: =O12-T12 -> 1180.658 | V12: =U12/O12 -> 0.44821275 | W12: JD-TCI-BG4-BU4-CAP | X12: CAP | Y12: Rajesh Radhakrishnan Nair | Z12: Seshakishore Kumar Kollipara | AA12: Shailendra Gupta | AB12: Arun Kumar Mishra | AC12: BG4 | AD12: BG4-BU4 | AE12: 9 | AF12: INR
A13: 1015565 | B13: Mithun Jayswal | C13: Active | D13: Permanent | E13: Sr. Software Engineer | F13: Rajesh Radhakrishnan Nair | G13: BG4 | H13: BG4-BU4 | I13: Mainframe | J13: Billable | K13: Billable | L13: 100 | M13: 1700 | N13: 0.012195122 | O13: =(L13/100)*M13*N13*(20*AE13) -> 3731.7073 | P13: 1201008 | Q13: 300000 | R13: =IFERROR(P13*(L13/100),"-") -> 1201008 | S13: =IFERROR(Q13*(L13/100),"-") -> 300000 | T13: =IFERROR((R13+S13)/(86*12),"-") -> 1454.4651 | U13: =O13-T13 -> 2277.2422 | V13: =U13/O13 -> 0.61024137 | W13: JD-TCI-BG4-BU4-CAP | X13: CAP | Y13: Rajesh Radhakrishnan Nair | Z13: Seshakishore Kumar Kollipara | AA13: Shailendra Gupta | AB13: Arun Kumar Mishra | AC13: BG4 | AD13: BG4-BU4 | AE13: 9 | AF13: INR
... A83: 1014173 | B83: Manuja Ashok Kshirsagar | C83: Active | D83: Permanent | E83: Project Manager | F83: Rajesh Radhakrishnan Nair | G83: BG5 | H83: BG5-BU1 | I83: Agile Consulting | J83: Billable | K83: Billable | L83: 100 | M83: 1800 | N83: 0.012195122 | O83: =(L83/100)*M83*N83*(20*AE83) -> 3951.2195 | P83: 2785000 | Q83: 300000 | R83: =IFERROR(P83*(L83/100),"-") -> 2785000 | S83: =IFERROR(Q83*(L83/100),"-") -> 300000 | T83: =IFERROR((R83+S83)/(86*12),"-") -> 2989.3411 | U83: =O83-T83 -> 961.87843 | V83: =U83/O83 -> 0.24343837 | W83: JD-TCI-BG4-BU4-CPS | X83: CPS | Y83: Nilesh W Bansodkar | Z83: Seshakishore Kumar Kollipara | AA83: Shailendra Gupta | AB83: Arun Kumar Mishra | AC83: BG4 | AD83: BG4-BU4 | AE83: 9 | AF83: INR
A84: 1017777 | B84: Swati Patil | I84: SAP | V84: 0.39047619 | X84: CPS
A85: 1101854 | B85: Harika Meka | I85: SAP | V85: 0.46428571 | X85: CPS
A86: 1101676 | B86: Priyanshu Chouhan | I86: SAP | V86: 0.46428571 | X86: CPS
A87: 1017094 | B87: Pravin Arvind Deshpande | C87: Active | D87: Permanent | E87: Sr. Software Engineer | F87: Nilesh W Bansodkar | G87: BG4 | H87: BG4-BU4 | I87: Content Management System (CMS) | J87: Billable | K87: Billable | L87: 100 | M87: 880 | N87: 0.012195122 | O87: =(L87/100)*M87*N87*(20*AE87) -> 1931.7073 | P87: 812508 | Q87: 300000 | R87: =IFERROR(P87*(L87/100),"-") -> 812508 | S87: =IFERROR(Q87*(L87/100),"-") -> 300000 | T87: =IFERROR((R87+S87)/(86*12),"-") -> 1078.0116 | U87: =O87-T87 -> 853.69569 | V87: =U87/O87 -> 0.44193842 | W87: JD-TCI-BG4-BU4-CPSS | X87: CPSS | Y87: Nilesh W Bansodkar | Z87: Seshakishore Kumar Kollipara | AA87: Shailendra Gupta | AB87: Arun Kumar Mishra | AC87: BG4 | AD87: BG4-BU4 | AE87: 9 | AF87: INR
A88: 1012750 | B88: Jeet Kumar Patidar | C88: Active | D88: Permanent | E88: Software Engineer | F88: Manish Gupta | G88: BG4 | H88: BG4-BU4 | I88: Java | J88: Billable | K88: Billable | L88: 100 | M88: 1400 | N88: 0.012195122 | O88: =(L88/100)*M88*N88*(20*AE88) -> 3073.1707 | P88: 862908 | Q88: 300000 | R88: =IFERROR(P88*(L88/100),"-") -> 862908 | S88: =IFERROR(Q88*(L88/100),"-") -> 300000 | T88: =IFERROR((R88+S88)/(86*12),"-") -> 1126.8488 | U88: =O88-T88 -> 1946.3219 | V88: =U88/O88 -> 0.63332697 | W88: JD-TCI-BG4-BU4-D&A | X88: D&A | Y88: Nilesh W Bansodkar | Z88: Seshakishore Kumar Kollipara | AA88: Shailendra Gupta | AB88: Arun Kumar Mishra | AC88: BG4 | AD88: BG4-BU4 | AE88: 9 | AF88: INR
A89: 1102109 | B89: Sradha Suman Dash | C89: Active | D89: Permanent | E89: Sr. Software Engineer | F89: Nilesh W Bansodkar | G89: BG5 | H89: BG5-BU12 | I89: Data & Analytics | J89: Billable | K89: Billable | L89: 100 | M89: 1700 | N89: 0.012195122 | O89: =(L89/100)*M89*N89*(20*AE89) -> 3731.7073 | P89: 1100004 | Q89: 300000 | R89: =IFERROR(P89*(L89/100),"-") -> 1100004 | S89: =IFERROR(Q89*(L89/100),"-") -> 300000 | T89: =IFERROR((R89+S89)/(86*12),"-") -> 1356.593 | U89: =O89-T89 -> 2375.1143 | V89: =U89/O89 -> 0.63646854 | W89: JD-TCI-BG4-BU4-D&A | X89: D&A | Y89: Nilesh W Bansodkar | Z89: Seshakishore Kumar Kollipara | AA89: Shailendra Gupta | AB89: Arun Kumar Mishra | AC89: BG4 | AD89: BG4-BU4 | AE89: 9 | AF89: INR
A90: 1016906 | B90: Jalasutram Durga Prasad | C90: Active | D90: Permanent | E90: Sr. Software Engineer | F90: Nilesh W Bansodkar | G90: BG4 | H90: BG4-BU4 | I90: Mainframe | J90: Billable | K90: Billable | L90: 100 | M90: 1500 | N90: 0.012195122 | O90: =(L90/100)*M90*N90*(20*AE90) -> 3292.6829 | P90: 1264008 | Q90: 300000 | R90: =IFERROR(P90*(L90/100),"-") -> 1264008 | S90: =IFERROR(Q90*(L90/100),"-") -> 300000 | T90: =IFERROR((R90+S90)/(86*12),"-") -> 1515.5116 | U90: =O90-T90 -> 1777.1713 | V90: =U90/O90 -> 0.53973351 | W90: JD-TCI-BG4-BU4-D&A | X90: D&A | Y90: Nilesh W Bansodkar | Z90: Seshakishore Kumar Kollipara | AA90: Shailendra Gupta | AB90: Arun Kumar Mishra | AC90: BG4 | AD90: BG4-BU4 | AE90: 9 | AF90: INR
A91: 1102035 | B91: Aniket Krushnat Gaikwad | C91: Active | D91: Permanent | E91: Sr. Software Engineer | F91: Nilesh W Bansodkar | G91: BG4 | H91: BG4-BU4 | I91: Java | J91: Billable | K91: Billable | L91: 100 | M91: 1200 | N91: 0.012195122 | O91: =(L91/100)*M91*N91*(20*AE91) -> 2634.1463 | P91: 1350000 | Q91: 300000 | R91: =IFERROR(P91*(L91/100),"-") -> 1350000 | S91: =IFERROR(Q91*(L91/100),"-") -> 300000 | T91: =IFERROR((R91+S91)/(86*12),"-") -> 1598.8372 | U91: =O91-T91 -> 1035.3091 | V91: =U91/O91 -> 0.39303402 | W91: JD-TCI-BG4-BU4-D&A | X91: D&A | Y91: Nilesh W Bansodkar | Z91: Seshakishore Kumar Kollipara | AA91: Shailendra Gupta | AB91: Arun Kumar Mishra | AC91: BG4 | AD91: BG4-BU4 | AE91: 9 | AF91: INR
A92: 1100468 | B92: Pooja Ashok Ambawle | C92: Active | D92: Permanent | E92: Sr. Software Engineer | F92: Nilesh W Bansodkar | G92: BG4 | H92: BG4-BU4 | I92: Mainframe | J92: Billable | K92: Billable | L92: 100 | M92: 1800 | N92: 0.012195122 | O92: =(L92/100)*M92*N92*(20*AE92) -> 3951.2195 | P92: 1500000 | Q92: 300000 | R92: =IFERROR(P92*(L92/100),"-") -> 1500000 | S92: =IFERROR(Q92*(L92/100),"-") -> 300000 | T92: =IFERROR((R92+S92)/(86*12),"-") -> 1744.186 | U92: =O92-T92 -> 2207.0335 | V92: =U92/O92 -> 0.5585702 | W92: JD-TCI-BG4-BU4-D&A | X92: D&A | Y92: Nilesh W Bansodkar | Z92: Seshakishore Kumar Kollipara | AA92: Shailendra Gupta | AB92: Arun Kumar Mishra | AC92: BG4 | AD92: BG4-BU4 | AE92: 9 | AF92: INR
A93: 1101688 | B93: Shantanu Mithilesh Moraskr | C93: Active | D93: Permanent | E93: Sr. Software Engineer | F93: Nilesh W Bansodkar | G93: BG4 | H93: BG4-BU4 | I93: Java | J93: Billable | K93: Billable | L93: 100 | M93: 1700 | N93: 0.012195122 | O93: =(L93/100)*M93*N93*(20*AE93) -> 3731.7073 | P93: 1500000 | Q93: 300000 | R93: =IFERROR(P93*(L93/100),"-") -> 1500000 | S93: =IFERROR(Q93*(L93/100),"-") -> 300000 | T93: =IFERROR((R93+S93)/(86*12),"-") -> 1744.186 | U93: =O93-T93 -> 1987.5213 | V93: =U93/O93 -> 0.53260374 | W93: JD-TCI-BG4-BU4-D&A | X93: D&A | Y93: Nilesh W Bansodkar | Z93: Seshakishore Kumar Kollipara | AA93: Shailendra Gupta | AB93: Arun Kumar Mishra | AC93: BG4 | AD93: BG4-BU4 | AE93: 9 | AF93: INR
A94: 1017691 | B94: Deepa Basavaraj Patil | C94: Active | D94: Permanent | E94: UI Specialist | F94: Nilesh W Bansodkar | G94: BG5 | H94: BG5-BU1 | I94: User Interface (UI) | J94: Billable | K94: Billable | L94: 100 | M94: 1800 | N94: 0.012195122 | O94: =(L94/100)*M94*N94*(20*AE94) -> 3951.2195 | P94: 1561800 | Q94: 300000 | R94: =IFERROR(P94*(L94/100),"-") -> 1561800 | S94: =IFERROR(Q94*(L94/100),"-") -> 300000 | T94: =IFERROR((R94+S94)/(86*12),"-") -> 1804.0698 | U94: =O94-T94 -> 2147.1497 | V94: =U94/O94 -> 0.54341444 | W94: JD-TCI-BG4-BU4-D&A | X94: D&A | Y94: Nilesh W Bansodkar | Z94: Seshakishore Kumar Kollipara | AA94: Shailendra Gupta | AB94: Arun Kumar Mishra | AC94: BG4 | AD94: BG4-BU4 | AE94: 9 | AF94: INR
A95: 1100163 | B95: Akash Sahebrao Kadhane | C95: Active | D95: Permanent | E95: Sr. Software Engineer | F95: Nilesh W Bansodkar | G95: BG5 | H95: BG5-BU12 | I95: Data & Analytics | J95: Billable | K95: Billable | L95: 100 | M95: 2100 | N95: 0.012195122 | O95: =(L95/100)*M95*N95*(20*AE95) -> 4609.7561 | P95: 1650000 | Q95: 300000 | R95: =IFERROR(P95*(L95/100),"-") -> 1650000 | S95: =IFERROR(Q95*(L95/100),"-") -> 300000 | T95: =IFERROR((R95+S95)/(86*12),"-") -> 1889.5349 | U95: =O95-T95 -> 2720.2212 | V95: =U95/O95 -> 0.5901009 | W95: JD-TCI-BG4-BU4-D&A | X95: D&A | Y95: Nilesh W Bansodkar | Z95: Seshakishore Kumar Kollipara | AA95: Shailendra Gupta | AB95: Arun Kumar Mishra | AC95: BG4 | AD95: BG4-BU4 | AE95: 9 | AF95: INR
A96: 1102115 | B96: Sneha Balaram Yadav | C96: Active | D96: Permanent | E96: Sr. Software Engineer | F96: Nilesh W Bansodkar | G96: BG5 | H96: BG5-BU12 | I96: Data & Analytics | J96: Billable | K96: Billable | L96: 100 | M96: 1700 | N96: 0.012195122 | O96: =(L96/100)*M96*N96*(20*AE96) -> 3731.7073 | P96: 1800000 | Q96: 300000 | R96: =IFERROR(P96*(L96/100),"-") -> 1800000 | S96: =IFERROR(Q96*(L96/100),"-") -> 300000 | T96: =IFERROR((R96+S96)/(86*12),"-") -> 2034.8837 | U96: =O96-T96 -> 1696.8236 | V96: =U96/O96 -> 0.45470436 | W96: JD-TCI-BG4-BU4-D&A | X96: D&A | Y96: Nilesh W Bansodkar | Z96: Seshakishore Kumar Kollipara | AA96: Shailendra Gupta | AB96: Arun Kumar Mishra | AC96: BG4 | AD96: BG4-BU4 | AE96: 9 | AF96: INR
A97: 1100076 | B97: Rahul Manohar Mhakave | C97: Active | D97: Permanent | E97: Sr. Software Engineer | F97: Nilesh W Bansodkar | G97: BG5 | H97: BG5-BU12 | I97: Data & Analytics | J97: Billable | K97: Billable | L97: 100 | M97: 2100 | N97: 0.012195122 | O97: =(L97/100)*M97*N97*(20*AE97) -> 4609.7561 | P97: 1850004 | Q97: 300000 | R97: =IFERROR(P97*(L97/100),"-") -> 1850004 | S97: =IFERROR(Q97*(L97/100),"-") -> 300000 | T97: =IFERROR((R97+S97)/(86*12),"-") -> 2083.3372 | U97: =O97-T97 -> 2526.4189 | V97: =U97/O97 -> 0.54805912 | W97: JD-TCI-BG4-BU4-D&A | X97: D&A | Y97: Nilesh W Bansodkar | Z97: Seshakishore Kumar Kollipara | AA97: Shailendra Gupta | AB97: Arun Kumar Mishra | AC97: BG4 | AD97: BG4-BU4 | AE97: 9 | AF97: INR
A98: 1000110 | B98: Jai Kumar Gadoeya | C98: Active | D98: Permanent | E98: Sr. Tech Lead | F98: Manish Gupta | G98: BG4 | H98: BG4-BU4 | I98: Java | J98: Billable | K98: Billable | L98: 100 | M98: 2100 | N98: 0.012195122 | O98: =(L98/100)*M98*N98*(20*AE98) -> 4609.7561 | P98: 2500000 | Q98: 300000 | R98: =IFERROR(P98*(L98/100),"-") -> 2500000 | S98: =IFERROR(Q98*(L98/100),"-") -> 300000 | T98: =IFERROR((R98+S98)/(86*12),"-") -> 2713.1783 | U98: =O98-T98 -> 1896.5778 | V98: =U98/O98 -> 0.41142693 | W98: JD-TCI-BG4-BU4-D&A | X98: D&A | Y98: Nilesh W Bansodkar | Z98: Seshakishore Kumar Kollipara | AA98: Shailendra Gupta | AB98: Arun Kumar Mishra | AC98: BG4 | AD98: BG4-BU4 | AE98: 9 | AF98: INR
... A109: 1009357 | B109: Harshal Ketan Patil | C109: Active | D109: Permanent | E109: Module Lead | F109: Nilesh W Bansodkar | G109: BG4 | H109: BG4-BU4 | I109: Java | J109: Billable | K109: Billable | L109: 100 | M109: 1800 | N109: 0.012195122 | O109: =(L109/100)*M109*N109*(20*AE109) -> 3951.2195 | P109: 1550308 | Q109: 300000 | R109: =IFERROR(P109*(L109/100),"-") -> 1550308 | S109: =IFERROR(Q109*(L109/100),"-") -> 300000 | T109: =IFERROR((R109+S109)/(86*12),"-") -> 1792.9341 | U109: =O109-T109 -> 2158.2854 | V109: =U109/O109 -> 0.54623273 | W109: JD-TCI-BG4-BU4-Foundry | X109: Foundry | Y109: Nilesh W Bansodkar | Z109: Seshakishore Kumar Kollipara | AA109: Shailendra Gupta | AB109: Arun Kumar Mishra | AC109: BG4 | AD109: BG4-BU4 | AE109: 9 | AF109: INR
A110: 1009797 | B110: Vivek Anaskar | I110: SAP | V110: 0.30933333 | X110: HCM
A111: 1005201 | B111: Vijaya Ganapa | I111: SAP | V111: 0.54711111 | X111: HCM
A112: 1004516 | B112: Bhaskar Yellamanchili | I112: SAP | V112: 0.49072222 | X112: HCM
A113: 1102205 | B113: Shivam Gopal Kayarkar | C113: Active | D113: Permanent | E113: Consultant | F113: Nilesh W Bansodkar | G113: BG5 | H113: BG5-BU15 | I113: ServiceNow | J113: Billable | K113: Billable | L113: 100 | M113: 1700 | N113: 0.012195122 | O113: =(L113/100)*M113*N113*(20*AE113) -> 3731.7073 | P113: 1389395 | Q113: 300000 | R113: =IFERROR(P113*(L113/100),"-") -> 1389395 | S113: =IFERROR(Q113*(L113/100),"-") -> 300000 | T113: =IFERROR((R113+S113)/(86*12),"-") -> 1637.0107 | U113: =O113-T113 -> 2094.6966 | V113: =U113/O113 -> 0.56132393 | W113: JD-TCI-BG4-BU4-I&O | X113: I&O | Y113: Nilesh W Bansodkar | Z113: Seshakishore Kumar Kollipara | AA113: Shailendra Gupta | AB113: Arun Kumar Mishra | AC113: BG4 | AD113: BG4-BU4 | AE113: 9 | AF113: INR
A114: 1100814 | B114: Kale Laxmikant Vitthalrao | C114: Active | D114: Permanent | E114: Software Engineer | F114: Nilesh W Bansodkar | G114: BG5 | H114: BG5-BU12 | I114: Data & Analytics | J114: Billable | K114: Billable | L114: 100 | M114: 1200 | N114: 0.012195122 | O114: =(L114/100)*M114*N114*(20*AE114) -> 2634.1463 | P114: 1050000 | Q114: 300000 | R114: =IFERROR(P114*(L114/100),"-") -> 1050000 | S114: =IFERROR(Q114*(L114/100),"-") -> 300000 | T114: =IFERROR((R114+S114)/(86*12),"-") -> 1308.1395 | U114: =O114-T114 -> 1326.0068 | V114: =U114/O114 -> 0.50339147 | W114: JD-TCI-BG4-BU4-I&O | X114: I&O | Y114: Nilesh W Bansodkar | Z114: Seshakishore Kumar Kollipara | AA114: Shailendra Gupta | AB114: Arun Kumar Mishra | AC114: BG4 | AD114: BG4-BU4 | AE114: 9 | AF114: INR
A115: 1007362 | B115: Anwar Bashirahmad Kudle | C115: Active | D115: Permanent | E115: Sr. Consultant | F115: Nilesh W Bansodkar | G115: BG5 | H115: BG5-BU9 | I115: Core-Infra | J115: Billable | K115: Billable | L115: 100 | M115: 1700 | N115: 0.012195122 | O115: =(L115/100)*M115*N115*(20*AE115) -> 3731.7073 | P115: 1891000 | Q115: 300000 | R115: =IFERROR(P115*(L115/100),"-") -> 1891000 | S115: =IFERROR(Q115*(L115/100),"-") -> 300000 | T115: =IFERROR((R115+S115)/(86*12),"-") -> 2123.062 | U115: =O115-T115 -> 1608.6453 | V115: =U115/O115 -> 0.43107488 | W115: JD-TCI-BG4-BU4-I&O | X115: I&O | Y115: Nilesh W Bansodkar | Z115: Seshakishore Kumar Kollipara | AA115: Shailendra Gupta | AB115: Arun Kumar Mishra | AC115: BG4 | AD115: BG4-BU4 | AE115: 9 | AF115: INR
A116: 1008531 | B116: Prachi Sanmesh Kale | C116: Active | D116: Permanent | E116: Tech Lead | F116: Nilesh W Bansodkar | G116: BG4 | H116: BG4-BU4 | I116: Java | J116: Billable | K116: Billable | L116: 100 | M116: 1800 | N116: 0.012195122 | O116: =(L116/100)*M116*N116*(20*AE116) -> 3951.2195 | P116: 1948508 | Q116: 300000 | R116: =IFERROR(P116*(L116/100),"-") -> 1948508 | S116: =IFERROR(Q116*(L116/100),"-") -> 300000 | T116: =IFERROR((R116+S116)/(86*12),"-") -> 2178.7868 | U116: =O116-T116 -> 1772.4327 | V116: =U116/O116 -> 0.44857864 | W116: JD-TCI-BG4-BU4-I&O | X116: I&O | Y116: Nilesh W Bansodkar | Z116: Seshakishore Kumar Kollipara | AA116: Shailendra Gupta | AB116: Arun Kumar Mishra | AC116: BG4 | AD116: BG4-BU4 | AE116: 9 | AF116: INR
A117: 1100752 | B117: Priti Subhash Naik | C117: Active | D117: Permanent | E117: Consultant | F117: Nilesh W Bansodkar | G117: BG5 | H117: BG5-BU15 | I117: ServiceNow | J117: Billable | K117: Billable | L117: 100 | M117: 1800 | N117: 0.012195122 | O117: =(L117/100)*M117*N117*(20*AE117) -> 3951.2195 | P117: 2100000 | Q117: 300000 | R117: =IFERROR(P117*(L117/100),"-") -> 2100000 | S117: =IFERROR(Q117*(L117/100),"-") -> 300000 | T117: =IFERROR((R117+S117)/(86*12),"-") -> 2325.5814 | U117: =O117-T117 -> 1625.6381 | V117: =U117/O117 -> 0.41142693 | W117: JD-TCI-BG4-BU4-I&O | X117: I&O | Y117: Nilesh W Bansodkar | Z117: Seshakishore Kumar Kollipara | AA117: Shailendra Gupta | AB117: Arun Kumar Mishra | AC117: BG4 | AD117: BG4-BU4 | AE117: 9 | AF117: INR
A118: 1101611 | B118: Prabin Kumar Baitharu | C118: Active | D118: Permanent | E118: Sr. Consultant | F118: Nilesh W Bansodkar | G118: BG5 | H118: BG5-BU15 | I118: ServiceNow | J118: Billable | K118: Billable | L118: 100 | M118: 2100 | N118: 0.012195122 | O118: =(L118/100)*M118*N118*(20*AE118) -> 4609.7561 | P118: 2800000 | Q118: 300000 | R118: =IFERROR(P118*(L118/100),"-") -> 2800000 | S118: =IFERROR(Q118*(L118/100),"-") -> 300000 | T118: =IFERROR((R118+S118)/(86*12),"-") -> 3003.876 | U118: =O118-T118 -> 1605.8801 | V118: =U118/O118 -> 0.34836553 | W118: JD-TCI-BG4-BU4-I&O | X118: I&O | Y118: Nilesh W Bansodkar | Z118: Seshakishore Kumar Kollipara | AA118: Shailendra Gupta | AB118: Arun Kumar Mishra | AC118: BG4 | AD118: BG4-BU4 | AE118: 9 | AF118: INR
A119: 1100287 | B119: Shardullya Vikram Singh | C119: Active | D119: Permanent | E119: Sr. Software Engineer | F119: Rajesh Radhakrishnan Nair | G119: BG4 | H119: BG4-BU4 | I119: Mobility | J119: Billable | K119: Billable | L119: 100 | M119: 1400 | N119: 0.012195122 | O119: =(L119/100)*M119*N119*(20*AE119) -> 3073.1707 | P119: 1326108 | Q119: 300000 | R119: =IFERROR(P119*(L119/100),"-") -> 1326108 | S119: =IFERROR(Q119*(L119/100),"-") -> 300000 | T119: =IFERROR((R119+S119)/(86*12),"-") -> 1575.686 | U119: =O119-T119 -> 1497.4847 | V119: =U119/O119 -> 0.48727676 | W119: JD-TCI-BG4-BU4-ISG | X119: ISG | Y119: Rajesh Radhakrishnan Nair | Z119: Seshakishore Kumar Kollipara | AA119: Shailendra Gupta | AB119: Arun Kumar Mishra | AC119: BG4 | AD119: BG4-BU4 | AE119: 9 | AF119: INR
...

Sheet Sheet3
C2: Row Labels | D2: Sum of Profit%
C3: CAP | D3: 19.593167
C4: CPS | D4: 21.799754
C5: CPSS | D5: 0.44193842
C6: D&A | D6: 5.8414427
C7: Ecommerce | D7: 2.9420271
C8: ETEC | D8: 0.3893525
C9: Foundry | D9: 2.0557156
C10: HCM | D10: 1.3471667
C11: I&O | D11: 2.7041614
C12: ISG | D12: 5.1222139
C13: IT Finance | D13: 2.7251831
C14: JDF | D14: 4.9300365
... C20: Grand Total | D20: 99.349122
C25: CAP | D25: =4779%/100 -> 0.4779
C26: CPS | D26: =4954%/100 -> 0.4954
C27: CPSS | D27: =4419%/100 -> 0.4419
C28: D&A | D28: =5310%/100 -> 0.531
C29: eCommerce | D29: =4903%/100 -> 0.4903
C30: ETEC | D30: =3894%/100 -> 0.3894
C31: Foundry | D31: =5139%/100 -> 0.5139
C32: HCM | D32: =4491%/100 -> 0.4491
C33: I&O | D33: =4507%/100 -> 0.4507
C34: ISG | D34: =4269%/100 -> 0.4269
C35: IT Finance | D35: =4542%/100 -> 0.4542
C36: JDF | D36: =4930%/100 -> 0.493
C37: MSP | D37: =4637%/100 -> 0.4637
C38: OM | D38: =5549%/100 -> 0.5549
C39: PDC | D39: =4465%/100 -> 0.4465
C40: PDP | D40: =5220%/100 -> 0.522
C41: R1OF | D41: =4137%/100 -> 0.4137

Sheet Employee detail
A1: Sr no | B1: YASH Emp ID | C1: Name | D1: Contingent/Contractor | E1: Status | F1: Domain | G1: Group Name | H1: Skill | I1: Sub Skill | J1: Biling Rate in INR
A2: 1 | B2: 1000111 | C2: Madhu Smitha Kola | D2: Contractor | E2: Active | F2: IT Finance | G2: IT Finance | H2: SAP | I2: SAP FI | J2: 2100
A3: 2 | B3: 1004759 | C3: Anoop Halder | D3: Contingent | E3: Active | F3: PDP | G3: Product Design PV&V | H3: Testing | I3: QA | J3: 1400
A4: 3 | B4: 1005949 | C4: Sreedhar Reddy Bonala | D4: Contractor | E4: Active | F4: PDC | G4: Parts Mordenization | H4: SAP | I4: SAP CRM | J4: 1500
A5: 4 | B5: 1007148 | C5: Atul Laxmanrao Vairale | D5: Contingent | E5: Active | F5: CPS | G5: CPS- Resolution and Information | H5: Fullstack | I5: JAVA | J5: 1800
A6: 5 | B6: 1007362 | C6: Anwar Bashirahmad Kudle | D6: Contingent | E6: Active | F6: I&O | G6: Platform Services/Cloud | H6: Mainframe | I6: DBA | J6: 1700
A7: 6 | B7: 1006932 | C7: Vikram Karan Pingale | D7: Contingent | E7: Active | F7: ISG | G7: ISG - Digital, Shared Services | H7: Testing | I7: QA | J7: 2000
A8: 7 | B8: 1008048 | C8: Mahesh Anil Thokala | D8: Contingent | E8: Active | F8: CPS | G8: CPS - Proactive Services | H8: Testing | I8: QA | J8: 1400
A9: 8 | B9: 1008172 | C9: Shailendrakumar Amarsing Vasave | D9: Contingent | E9: Active | F9: PDP | G9: Product Design PV&V | H9: SQL Server DBA | I9: .NET | J9: 1700
A10: 9 | B10: 1008473 | C10: Jyoti Singh | D10: Contingent | E10: Inactive | F10: ISG | G10: ISG - Digital, Reprogramming and Activation | H10: Testing | I10: QA | J10: 1160
A11: 10 | B11: 1008531 | C11: Prachi Sanmesh Kale | D11: Contingent | E11: Active | F11: I&O | G11: Platform Services/Cloud | H11: Fullstack | I11: JAVA Cloud | J11: 1800
A12: 11 | B12: 1009357 | C12: Harshal Ketan Patil | D12: Contingent | E12: Active | F12: Foundry | G12: Quality & Reliability | H12: Fullstack | I12: JAVA | J12: 1800
A13: 12 | B13: 1009451 | C13: Vrushabh Abhaykumar Wakhariya | D13: Contingent | E13: Active | F13: Ecommerce | G13: Channel Systems & Services | H13: Fullstack | I13: JAVA | J13: 1700
... A75: 74 | B75: 1016619 | C75: Pratik Venkatesh Kurbet | D75: Contingent | E75: Active | F75: CPS | G75: CPS- Resolution and Information | H75: Fullstack | I75: JAVA | J75: 1700
A76: 75 | B76: 1011907 | C76: Nayan Pimpare | D76: Project | E76: Active | F76: MSP | G76: Manufacturing Engineering | H76: UI/UX | I76: UI | J76: Fixed Bid
A77: 76 | B77: 1600057 | C77: Shaaleen Mohammad Afsar Syed Hussain | D77: Contractor | E77: Active | F77: PDC | G77: Parts Order management | H77: SAP | I77: SAP BODS | J77: 1800
A78: 77 | B78: 1017372 | C78: Aadesh Mishra | D78: Contingent | E78: Active | F78: PDP | G78: Product Data Management | H78: Fullstack | I78: Fullstack | J78: 1700
A79: 78 | B79: 1017347 | C79: Sai Krishna Doodla | D79: Contingent | E79: Active | F79: PDC | G79: Parts Warehousing, Planning | H79: Mainframe | I79: Mainframe | J79: 1700
A80: 79 | B80: 1017397 | C80: Akash Jadhav | D80: Contingent | E80: Active | F80: CPS | G80: CPS- Resolution and Information | H80: DATA | I80: Python | J80: 1800
A81: 80 | B81: 1601535 | C81: Yanamadala Sasidhar | D81: Contingent | E81: Active | F81: PDC | G81: Parts Mordenization | H81: SAP | I81: SAP CRM | J81: 2350
A82: 81 | B82: 1017492 | C82: Vatsal Shah Dharmendra | D82: Contingent | E82: Active | F82: CPS | G82: CPS - Proactive Services | H82: Fullstack | I82: Embedded C++ | J82: 1800
A83: 82 | B83: 1016969 | C83: Venkataraman J | D83: Contingent | E83: Active | F83: PDP | G83: Product Data management | H83: SAP | I83: SAP | J83: 1800
A84: 83 | B84: 1015753 | C84: Sushant Temkar | D84: Project | E84: Active | F84: MSP | G84: Manufacturing Engineering | H84: Fullstack | I84: Fullstack | J84: Fixed Bid
A85: 84 | B85: 1016893 | C85: Mahima Shrivastav | D85: Contingent | E85: Active | F85: CPS | G85: CPS- Resolution and Information | H85: Fullstack | I85: Core Java | J85: 1200
A86: 85 | B86: 1016671 | C86: Shubham Patil | D86: Contingent | E86: Active | F86: JDF | G86: DevOps Operations | H86: Fullstack | I86: Java | J86: 1200
A87: 86 | B87: 1017512 | C87: Mayur Sontale | D87: Contingent | E87: Active | F87: JDF | G87: JDF - Platform Services | H87: Fullstack | I87: Java Aws | J87: 1800
A88: 87 | B88: 1004516 | C88: Bhaskar Yellamanchili | D88: Contractor | E88: Active | F88: HCM | G88: HR and Corporate Functions | H88: SAP | I88: SAP HR | J88: 1800
A89: 88 | B89: 1015066 | C89: Aman Kumar 1 | D89: Contingent | E89: Active | F89: CPS | G89: CPS - Proactive Services | H89: Fullstack | I89: JAVA+React | J89: 1200
A90: 89 | B90: 1013812 | C90: Jeshwant Kumar Kolan | D90: Contingent | E90: Active | F90: IT Finance | G90: IT Finance | H90: SAP | I90: SAP ABAP | J90: 1400
A91: 90 | B91: 1014208 | C91: Priyanshi Zamindar | D91: Contingent | E91: Active | F91: ETEC | G91: ETEC | H91: Fullstack | I91: JAVA+React | J91: 1700
A92: 91 | B92: 1015478 | C92: Ramdas Buttanwad | D92: Contingent | E92: Active | F92: ISG | G92: ISG - Digital | H92: Fullstack | I92: Java Script | J92: 1300
A93: 92 | B93: 1016683 | C93: Shubhangi Kamble | D93: Project | E93: Active | F93: MSP | G93: Manufacturing Engineering | H93: Fullstack | I93: Fullstack | J93: Fixed Bid
A94: 93 | B94: 1100011 | C94: Manish Madhukar Yadav | D94: Contingent | E94: Active | F94: Ecommerce | G94: Ecommerce | H94: DATA | I94: Data Engenniering | J94: 1700
A95: 94 | B95: 1601630 | C95: Balineni Kiran Kumar Reddy | D95: Contingent | E95: Active | F95: PDC | G95: Parts Warehousing, Planning | H95: SAP | I95: SAP CRM | J95: 2350
A96: 95 | B96: 1017777 | C96: Swati Patil | D96: Contingent | E96: Active | F96: CPS | G96: CPS- Resolution and Information | H96: SAP | I96: SAP ABAP | J96: 2100
A97: 96 | B97: 1601627 | C97: Sravani Ananthapalli | D97: Project | E97: Active | F97: MSP | G97: Manufacturing Engineering | H97: SAP | I97: SAP ABAP | J97: Fixed Bid
A98: 97 | B98: 1012589 | C98: Sowjanya Parthasarathi | D98: Project | E98: Active | F98: MSP | G98: Manufacturing Engineering | H98: SAP | I98: SAP PI/PO | J98: Fixed Bid
A99: 98 | B99: 1100076 | C99: Rahul Mhakave | D99: Contingent | E99: Active | F99: D&A | G99: Data Products | H99: DATA | I99: Data engineering | J99: 2100
A100: 99 | B100: 1100051 | C100: Akash Bhutwani | D100: Contingent | E100: Active | F100: IT Finance | G100: IT Finance | H100: SAP | I100: SAP | J100: 1700
A101: 100 | B101: 1006133 | C101: Vishal Sarathe | D101: Contingent | E101: Active | F101: ISG | G101: ISG - Digital | H101: Testing | I101: Testing | J101: 1800
...
